Workbook

Sheet Data Cruda
A1: Año | B1: Fecha | C1: Mes | D1: Cliente | E1: Descripción | F1: PAÍS | G1: ZONA | H1: DEPARTAMENTO | I1: Sector | J1: Refrigerante | K1: Importe total | L1: TIPO DE PROYECTO | M1: CODIGO PROYECTO | N1: Columna1 | O1: Margen Comercial | P1: MARGEN COMERCIAL2 | Q1: Descripción2
A2: 2014 | B2: 41641 | C2: Enero | D2: REFRINDUS EIRL | E2: - BOTELLAS DE REFRIGERANTE | F2: PERÚ | G2: SUR | H2: ICA | I2: OTROS | J2: Glicol | K2: 738.56 | O2: 0 | P2: 0
A3: 2014 | B3: 41642 | C3: Enero | D3: METALMECANICA PAV E.I.R.L. | E3: - DILUYENTE JETPOXY 100, JET 70MP BLANCO HR (A+ B | F3: PERÚ | G3: SUR | H3: ICA | I3: OTROS | J3: Venta directa | K3: 2180.68 | O3: 0 | P3: 0
A4: 2014 | B4: 41642 | C4: Enero | D4: AGRICOLA CHAPI SA | E4: - 2 PARES DE RESISTENCIA ELECTRICA DE BANDEJA DE | F4: PERÚ | G4: SUR | H4: ICA | I4: OTROS | J4: Venta directa | K4: 980 | O4: 0 | P4: 0
A5: 2014 | B5: 41645 | C5: Enero | D5: SUN FRUITS EXPORTS S.A. | E5: - OF 0105PRESOSTATO DE BAJA KP1A, CON RESET AUTOM | F5: PERÚ | G5: SUR | H5: ICA | I5: OTROS | J5: Venta directa | K5: 400 | O5: 0 | P5: 0
A6: 2014 | B6: 41645 | C6: Enero | D6: RVR AGRO E.I.R.L. | E6: - OF 0102RESISTENCIAS PARA EVAPORADOR, DE ACERO I | F6: PERÚ | G6: SUR | H6: ICA | I6: OTROS | J6: Venta directa | K6: 1280 | O6: 0 | P6: 0
A7: 2014 | B7: 41645 | C7: Enero | D7: EMPACADORA Y PROCESADORA HUAMANI SAC | E7: - VENTILADOR EVAPORATIVO DE 48" | F7: PERÚ | G7: SUR | H7: ICA | I7: OTROS | J7: Venta directa | K7: 6600 | O7: 0 | P7: 0
A8: 2014 | B8: 41645 | C8: Enero | D8: CAMPOSOL S.A. | E8: - OF 0471EQUIPOSMATERIALES Y MANO DE OBRA | F8: PERÚ | G8: NORTE | H8: LA LIBERTAD | I8: OTROS | J8: Venta directa | K8: 8650 | O8: 0 | P8: 0
A9: 2014 | B9: 41646 | C9: Enero | D9: CORPORACION AGROLATINA S.A.C. | E9: - SERVICIO DE INSTALACION DE 8 SENSORES DE TEMPERA | F9: PERÚ | G9: SUR | H9: ICA | I9: OTROS | J9: Venta directa | K9: 9120 | O9: 0 | P9: 0
A10: 2014 | B10: 41648 | C10: Enero | D10: RVR AGRO E.I.R.L. | E10: - OF 0109HELICE WINGFAN DE 1035 MM. 6-9 | F10: PERÚ | G10: SUR | H10: ICA | I10: OTROS | J10: Venta directa | K10: 748.93 | O10: 0 | P10: 0
A11: 2014 | B11: 41653 | C11: Enero | D11: I Q F DEL PERU SA | E11: - OF 0101JUEGO DE MANIJAS PARA PUERTA CORREDERAJ | F11: PERÚ | G11: SUR | H11: ICA | I11: OTROS | J11: Venta directa | K11: 810 | O11: 0 | P11: 0
A12: 2014 | B12: 41655 | C12: Enero | D12: DANPER TRUJILLO S.A.C. | E12: - OF 0108INSTALACION DE AIRE ACONDICIONADO EN PLA | F12: PERÚ | G12: NORTE | H12: LA LIBERTAD | I12: OTROS | J12: Venta directa | K12: 450 | O12: 0 | P12: 0
A13: 2014 | B13: 41656 | C13: Enero | D13: TAL S.A. | E13: - EQUIPOS DE REFRIGERACION, PANELES Y PUERTAS, INS | F13: PERÚ | G13: NORTE | H13: LA LIBERTAD | I13: PALTA | J13: Amoniaco | K13: 365000 | O13: 0 | P13: 0
... A610: 2017 | B610: 43098 | C610: Diciembre | D610: DANPER TRUJILLO S.A.C. | E610: MONTAJE DE TUNEL DE PALTA EN ZONA DE MADURACION | F610: PERÚ | G610: NORTE | H610: LA LIBERTAD | I610: OTROS | J610: Venta directa | K610: 1359.9 | O610: 0 | P610: 0
A611: 2018 | B611: 43101 | C611: Enero | D611: PASSION FRESH S.A.C | F611: PERÚ | G611: CENTRO | H611: CHIMBOTE | I611: UVA | J611: Freón | K611: 24447.23 | O611: 0 | P611: 0
A612: 2018 | B612: 43110 | C612: Enero | D612: CAMPOSOL S.A. | F612: PERÚ | G612: NORTE | H612: LA LIBERTAD | I612: ARANDANOS | J612: Amoniaco | K612: 1366897.5 | O612: 0 | P612: 0
A613: 2018 | B613: 43112 | C613: Enero | D613: ECO - ACUICOLA SOCIEDAD ANONIMA CERRADA | F613: PERÚ | G613: NORTE | H613: PIURA | I613: COMEDOR | J613: Otros | K613: 54590.94 | O613: 0 | P613: 0
A614: 2018 | B614: 43118 | C614: Enero | D614: SUN FRUITS EXPORTS S.A. | F614: PERÚ | G614: SUR | H614: ICA | I614: FRUTAS VARIAS | J614: Amoniaco | K614: 5349.2 | O614: 0 | P614: 0
A615: 2018 | B615: 43125 | C615: Enero | D615: T & T FRUITS S.A. | F615: PERÚ | G615: CENTRO | H615: HUARAL | I615: CITRICOS | J615: Freón | K615: 70966.95 | O615: 0 | P615: 0
A616: 2018 | B616: 43138 | C616: Febrero | D616: AGROPIURA S.A.C. | F616: PERÚ | G616: NORTE | H616: PIURA | I616: UVA | J616: Freón | K616: 400754.81 | O616: 0 | P616: 0
A617: 2018 | B617: 43139 | C617: Febrero | D617: INVERSIONES AGRICOLAS OLMOS S.A.C. | F617: PERÚ | G617: NORTE | H617: LAMBAYEQUE | I617: PALTA | J617: Freón | K617: 7462.03 | O617: 0 | P617: 0
A618: 2018 | B618: 43139 | C618: Febrero | D618: AGRICOLA SANTA AZUL S.A.C | F618: PERÚ | G618: CENTRO | H618: LIMA | I618: ARANDANOS | J618: Freón | K618: 415527.5 | O618: 0 | P618: 0
A619: 2018 | B619: 43141 | C619: Febrero | D619: TAL S.A. | F619: PERÚ | G619: NORTE | H619: LA LIBERTAD | I619: PALTA | J619: Amoniaco | K619: 245000.02 | O619: 0 | P619: 0
A620: 2018 | B620: 43143 | C620: Febrero | D620: TAL S.A. | F620: PERÚ | G620: NORTE | H620: LA LIBERTAD | I620: PALTA | J620: Amoniaco | K620: 106000 | O620: 0 | P620: 0
A621: 2018 | B621: 43143 | C621: Febrero | D621: AGROINDUSTRIAS AIB S.A | F621: PERÚ | G621: SUR | H621: ICA | I621: ESPARRAGOS | J621: Freón | K621: 151558.52 | O621: 0 | P621: 0
A622: 2018 | B622: 43147 | C622: Febrero | D622: SUN FRUITS EXPORTS S.A. | F622: PERÚ | G622: SUR | H622: ICA | I622: PALTA | J622: Amoniaco | K622: 53611.91 | O622: 0 | P622: 0
... A663: 2018 | B663: 43269 | C663: Junio | D663: AGROINVERSIONES VALLE Y PAMPA PERU SOCIEDAD ANONIMA | F663: PERÚ | G663: SUR | H663: ICA | I663: ARANDANOS | J663: Freón | K663: 59302.84 | O663: 0 | P663: 0
A664: 2018 | B664: 43270 | C664: Junio | D664: SOCIEDAD AGRICOLA RAPEL S.A.C. | E664: VENTA DE RACKS PARA CAMARAS | F664: PERÚ | G664: NORTE | H664: PIURA | I664: UVA | J664: Otros | K664: 20442 | O664: 0 | P664: 0
A665: 2018 | B665: 43274 | C665: Junio | D665: AGROINDUSTRIAS AIB S.A | F665: PERÚ | G665: SUR | H665: ICA | I665: ESPARRAGOS | J665: Freón | K665: 1280 | O665: 0 | P665: 0
A666: 2018 | B666: 43277 | C666: Junio | D666: HORTIFRUT-TAL S.A.C. | F666: PERÚ | G666: NORTE | H666: LA LIBERTAD | I666: FRUTAS VARIAS | J666: Amoniaco | K666: 23000 | O666: 0 | P666: 0
A667: 2018 | B667: 43284 | C667: Julio | D667: SOCIEDAD AGRICOLA DROKASA S.A. | F667: PERÚ | G667: SUR | H667: ICA | I667: COMEDOR | J667: Freón | K667: 1780.87 | O667: 0 | P667: 0
A668: 2018 | B668: 43286 | C668: Julio | D668: MANUELITA FYH S.A.C. | F668: PERÚ | G668: SUR | H668: ICA | I668: UVA | J668: Freón | K668: 2420 | O668: 0 | P668: 0
A669: 2018 | B669: 43289 | C669: Julio | D669: TAL S.A. | F669: PERÚ | G669: NORTE | H669: LA LIBERTAD | I669: FRUTAS VARIAS | J669: Freón | K669: 2790 | O669: 0 | P669: 0
A670: 2018 | B670: 43293 | C670: Julio | D670: SOCIEDAD AGRICOLA RAPEL S.A.C. | E670: VENTA DE RACKS PARA CAMARAS | F670: PERÚ | G670: NORTE | H670: PIURA | I670: UVA | J670: Otros | K670: 10221.4 | O670: 0 | P670: 0
A671: 2018 | B671: 43293 | C671: Julio | D671: AGRICOLA SAN JOSE S.A. | F671: PERÚ | G671: NORTE | H671: PIURA | I671: OTROS | J671: Otros | K671: 12884.07 | O671: 0 | P671: 0
A672: 2018 | B672: 43305 | C672: Julio | D672: RANSA COMERCIAL S A | F672: PERÚ | G672: CENTRO | H672: LIMA | I672: ARANDANOS | J672: Amoniaco | K672: 84560.77 | O672: 0 | P672: 0
A673: 2018 | B673: 43305 | C673: Julio | D673: AGRICOLA ANDREA S.A.C. | F673: PERÚ | G673: SUR | H673: ICA | I673: FRUTAS VARIAS | J673: Amoniaco | K673: 39268.93 | O673: 0 | P673: 0
A674: 2018 | B674: 43305 | C674: Julio | D674: AGRICOLA ANDREA S.A.C. | F674: PERÚ | G674: SUR | H674: ICA | I674: OTROS | J674: Venta directa | K674: 7000 | O674: 0 | P674: 0
A675: 2018 | B675: 43306 | C675: Julio | D675: MANUELITA FYH S.A.C. | F675: PERÚ | G675: SUR | H675: ICA | I675: UVA | J675: Freón | K675: 5280 | O675: 0 | P675: 0
A676: 2018 | B676: 43306 | C676: Julio | D676: MANUELITA FYH S.A.C. | F676: PERÚ | G676: SUR | H676: ICA | I676: OTROS | J676: Venta directa | K676: 504 | O676: 0 | P676: 0
...

Sheet OO.CC Y EEMM
A1: CODIGO PROYECTO | B1: Fecha | C1: Cliente | D1: venta total | E1: MARGEN DEL PROYECTO % | F1: VENTA DE OO.CC | G1: COSTO DE OO.CC | H1: %oocc | I1: VENTA DE EE.MM | J1: COSTO DE EE.MM | K1: %EEMM | L1: mg frío | M1: MARGEN FRIO AJUSTADO %
A2: PRY 2026-0000030 | B2: 46169 | C2: AGROBERRIES PERU S.A.C. | D2: 9500000 | E2: 0.13783493 | F2: 1610698 | G2: 1417414.3 | H2: 0.12 | I2: 2164509.8 | J2: 1928876.6 | K2: 0.10886214 | L2: 880514.93 | M2: 0.15380732
A3: PRY 2026-0000004 | B3: 46044 | C3: PROCESADORA TORRE BLANCA S.A.C | D3: 718498.3 | E3: 0.19456891 | F3: 99839.601 | G3: 89855.641 | H3: 0.1 | I3: 16663.672 | J3: 14830.668 | K3: 0.11 | L3: 127980.47 | M3: 0.21259389
A4: PRY 2025-0000058 | B4: 45881 | C4: IMBAREX S.A. | D4: 853450 | E4: 0.16949982 | F4: 0 | G4: 0 | H4: 0.1 | I4: 108374.26 | J4: 96453.091 | K4: 0.11 | L4: 132738.45 | M4: 0.17815431
A5: PRY 2025-0000042 | B5: 45838 | C5: EL PARQUE ALAYA PACKING S.A.C. | D5: 1490360.7 | E5: 0.17062136 | F5: 338909.16 | G5: 305018.24 | H5: 0.1 | I5: 384615.14 | J5: 342307.47 | K5: 0.11 | L5: 178088.79 | M5: 0.2322383
A6: PRY 2025-0000023 | B6: 45747 | C6: DANPER TRUJILLO S.A.C. | D6: 4440814 | E6: 0.15065946 | F6: 616879.8 | G6: 555191.82 | H6: 0.1 | I6: 1042789.2 | J6: 928082.41 | K6: 0.11 | L6: 492655.84 | M6: 0.17714137
A7: PRY 2025-0000006 | B7: 45705 | C7: AGROVISION PERU S.A.C. | D7: 815120.48 | E7: 0.14022488 | F7: 109347.88 | G7: 98413.092 | H7: 0.1 | I7: 18900 | J7: 16821 | K7: 0.11 | L7: 101286.38 | M7: 0.14746022
A8: PRY 2024-0000066 | B8: 45594 | C8: FAMILY FARMS PERÚ S.R.L. | D8: 1185464.3 | E8: 0.14071425 | F8: 176880 | G8: 159192 | H8: 0.1 | I8: 50528.8 | J8: 44970.632 | K8: 0.11 | L8: 143565.56 | M8: 0.14985098
A9: PRY 2024-0000027 | B9: 45415 | C9: AQU ANQA S.A.C. | D9: 670271.45 | E9: 0.13870204 | F9: 85639.18 | G9: 77075.262 | H9: 0.1 | I9: 122511.31 | J9: 109035.07 | K9: 0.11 | L9: 70927.858 | M9: 0.15348332
A10: PRY 2024-0000025 | B10: 45411 | C10: AGROVISION PERU S.A.C. | D10: 658743.34 | E10: 0.15300745 | F10: 64219.03 | G10: 57797.127 | H10: 0.1 | I10: 2370 | J10: 2109.3 | K10: 0.11 | L10: 94110.034 | M10: 0.15892823
A11: PRY 2024-0000010 | B11: 45345 | C11: QALI FRUITS S.A.C. | D11: 503000 | E11: 0.15393513 | F11: 103831.66 | G11: 93448.494 | H11: 0.1 | I11: 138791.32 | J11: 123524.27 | K11: 0.11 | L11: 51779.159 | M11: 0.19886225
A12: PRY 2024-0000003 | B12: 45299 | C12: AGROINDUSTRIAL ESTANISLAO DEL CHIMU S.A.C. | D12: 1136822.7 | E12: 0.18679355 | F12: 185668.63 | G12: 167101.77 | H12: 0.1 | I12: 110415.71 | J12: 98269.982 | K12: 0.11 | L12: 181638.56 | M12: 0.21604648
A13: PRY 2023-0000018 | B13: 45027 | C13: AGROFUTURA COMPANY S.A.C. | D13: 1283046.1 | E13: 0.18116751 | F13: 146606.24 | G13: 131945.62 | H13: 0.1 | I13: 44784.94 | J13: 39858.597 | K13: 0.11 | L13: 212859.29 | M13: 0.19498771
... A20: PRY 2021-0000003 | B20: 44208 | C20: CONSORCIO CARSOL - JRM S.A.C. | D20: 984777.26 | E20: 0.13948419 | F20: 142011.98 | G20: 127810.78 | H20: 0.1 | I20: 114196.07 | J20: 101634.5 | K20: 0.11 | L20: 110598.09 | M20: 0.15180177

Sheet 1. Ventas Anuales
A1: TABLA 1 – VENTAS MENSUALES + ACUMULADO POR AÑO (2021-2026)
A3: Año | B3: Ene | C3: Feb | D3: Mar | E3: Abr | F3: May | G3: Jun | H3: Jul | I3: Ago | J3: Sep | K3: Oct | L3: Nov | M3: Dic | N3: TOTAL
A4: 2021 | B4: 1810393 | C4: 1089231.8 | D4: 1116870.3 | E4: 2068493.4 | F4: 2505141.4 | G4: 3589383.9 | H4: 1917227.9 | I4: 1140241 | J4: 1276014.6 | K4: 33998.4 | L4: 1148205.3 | M4: 2615340.2 | N4: =SUM(B4:M4) -> 20310541
A5: Acum. | B5: =B4 -> 1810393 | C5: =B5+C4 -> 2899624.8 | D5: =C5+D4 -> 4016495.1 | E5: =D5+E4 -> 6084988.5 | F5: =E5+F4 -> 8590129.9 | G5: =F5+G4 -> 12179514 | H5: =G5+H4 -> 14096742 | I5: =H5+I4 -> 15236983 | J5: =I5+J4 -> 16512997 | ... M5: =L5+M4 -> 20310541 | N5: =M5 -> 20310541
A7: 2022 | B7: 229756.7 | C7: 3871835.6 | D7: 3602116.1 | E7: 6230558.3 | F7: 5222934.9 | G7: 1427789.9 | H7: 3476461.5 | I7: 1870213.4 | J7: 1212618.8 | K7: 142299.66 | L7: 1305489.6 | M7: 4607690.2 | N7: =SUM(B7:M7) -> 33199765
A8: Acum. | B8: =B7 -> 229756.7 | C8: =B8+C7 -> 4101592.3 | D8: =C8+D7 -> 7703708.4 | E8: =D8+E7 -> 13934267 | F8: =E8+F7 -> 19157202 | G8: =F8+G7 -> 20584991 | H8: =G8+H7 -> 24061453 | I8: =H8+I7 -> 25931666 | J8: =I8+J7 -> 27144285 | ... M8: =L8+M7 -> 33199765 | N8: =M8 -> 33199765
A10: 2023 | B10: 673094.91 | C10: 516516.52 | D10: 2410566.1 | E10: 1729388.8 | F10: 2771062.7 | G10: 993087.41 | H10: 1503733.1 | I10: 1039787.9 | J10: 27777.771 | K10: 594477.09 | L10: 1413141.5 | M10: 1616740.9 | N10: =SUM(B10:M10) -> 15289375
A11: Acum. | B11: =B10 -> 673094.91 | C11: =B11+C10 -> 1189611.4 | D11: =C11+D10 -> 3600177.6 | E11: =D11+E10 -> 5329566.4 | F11: =E11+F10 -> 8100629.1 | G11: =F11+G10 -> 9093716.5 | H11: =G11+H10 -> 10597450 | I11: =H11+I10 -> 11637238 | J11: =I11+J10 -> 11665015 | ... M11: =L11+M10 -> 15289375 | N11: =M11 -> 15289375
A13: 2024 | B13: 77019.72 | C13: 1168612.2 | D13: 3590756.6 | E13: 1626868.8 | F13: 3115787.7 | G13: 1156829.5 | H13: 1562515.9 | I13: 578585.72 | J13: 334648.88 | K13: 1672197.8 | L13: 470764.38 | M13: 96562.07 | N13: =SUM(B13:M13) -> 15451149
A14: Acum. | B14: =B13 -> 77019.72 | C14: =B14+C13 -> 1245632 | D14: =C14+D13 -> 4836388.6 | E14: =D14+E13 -> 6463257.4 | F14: =E14+F13 -> 9579045.1 | G14: =F14+G13 -> 10735875 | H14: =G14+H13 -> 12298390 | I14: =H14+I13 -> 12876976 | J14: =I14+J13 -> 13211625 | ... M14: =L14+M13 -> 15451149 | N14: =M14 -> 15451149
A16: 2025 | B16: 197251.4 | C16: 1096220.8 | D16: 6615418.1 | E16: 4607683.4 | F16: 2423434.7 | G16: 4274625.6 | H16: 888259.06 | I16: 5353130.5 | J16: 4071839.8 | K16: 1992459.2 | L16: 2432241 | M16: 1003760.8 | N16: =SUM(B16:M16) -> 34956324
A17: Acum. | B17: =B16 -> 197251.4 | C17: =B17+C16 -> 1293472.2 | D17: =C17+D16 -> 7908890.3 | E17: =D17+E16 -> 12516574 | F17: =E17+F16 -> 14940008 | G17: =F17+G16 -> 19214634 | H17: =G17+H16 -> 20102893 | I17: =H17+I16 -> 25456024 | J17: =I17+J16 -> 29527863 | ... M17: =L17+M16 -> 34956324 | N17: =M17 -> 34956324
A19: 2026 | B19: 4362015.8 | C19: 3578569.9 | D19: 481538.55 | E19: 4267062.1 | F19: 13044891 | G19: 2526579.3 | H19: 0 | I19: 0 | J19: 0 | K19: 0 | L19: 0 | M19: 0 | N19: =SUM(B19:M19) -> 28260657
A20: Acum. | B20: =B19 -> 4362015.8 | C20: =B20+C19 -> 7940585.7 | D20: =C20+D19 -> 8422124.2 | E20: =D20+E19 -> 12689186 | F20: =E20+F19 -> 25734078 | G20: =F20+G19 -> 28260657 | H20: =G20+H19 -> 28260657 | I20: =H20+I19 -> 28260657 | J20: =I20+J19 -> 28260657 | ... M20: =L20+M19 -> 28260657 | N20: =M20 -> 28260657
A22: TOTAL | B22: =B4+B7+B10+B13+B16+B19 -> 7349531.5 | C22: =C4+C7+C10+C13+C16+C19 -> 11320987 | D22: =D4+D7+D10+D13+D16+D19 -> 17817266 | E22: =E4+E7+E10+E13+E16+E19 -> 20530055 | F22: =F4+F7+F10+F13+F16+F19 -> 29083253 | G22: =G4+G7+G10+G13+G16+G19 -> 13968296 | H22: =H4+H7+H10+H13+H16+H19 -> 9348197.5 | I22: =I4+I7+I10+I13+I16+I19 -> 9981958.5 | ... M22: =M4+M7+M10+M13+M16+M19 -> 9940094.3 | N22: =SUM(B22:M22) -> 1.4746781e+08
A25: TABLA 2 – MARGEN PONDERADO MENSUAL (2021-2026)
A27: Año | B27: Ene | C27: Feb | D27: Mar | E27: Abr | F27: May | G27: Jun | H27: Jul | I27: Ago | J27: Sep | K27: Oct | L27: Nov | M27: Dic | N27: Final Año
A28: 2021 | B28: =IFERROR(SUMIFS('Data Cruda'!$P$2:$P$1801,'Data Cruda'!$A$2:$A$1801,2021,'Data Cruda'!$C$2:$C$1801,"Enero")/SUMIFS('Data Cruda'!$K$2:$K$1801,'Data Cruda'!$A$2:$A$1801,2021,'Data Cruda'!$C$2:$C$1801,"Enero"),0) -> 0.15808456 | C28: =IFERROR(SUMIFS('Data Cruda'!$P$2:$P$1801,'Data Cruda'!$A$2:$A$1801,2021,'Data Cruda'!$C$2:$C$1801,"Febrero")/SUMIFS('Data Cruda'!$K$2:$K$1801,'Data Cruda'!$A$2:$A$1801,2021,'Data Cruda'!$C$2:$C$1801,"Febrero"),0) -> 0.11613769 | D28: =IFERROR(SUMIFS('Data Cruda'!$P$2:$P$1801,'Data Cruda'!$A$2:$A$1801,2021,'Data Cruda'!$C$2:$C$1801,"Marzo")/SUMIFS('Data Cruda'!$K$2:$K$1801,'Data Cruda'!$A$2:$A$1801,2021,'Data Cruda'!$C$2:$C$1801,"Marzo"),0) -> 0.17338259 | E28: =IFERROR(SUMIFS('Data Cruda'!$P$2:$P$1801,'Data Cruda'!$A$2:$A$1801,2021,'Data Cruda'!$C$2:$C$1801,"Abril")/SUMIFS('Data Cruda'!$K$2:$K$1801,'Data Cruda'!$A$2:$A$1801,2021,'Data Cruda'!$C$2:$C$1801,"Abril"),0) -> 0.0038448476 | F28: =IFERROR(SUMIFS('Data Cruda'!$P$2:$P$1801,'Data Cruda'!$A$2:$A$1801,2021,'Data Cruda'!$C$2:$C$1801,"Mayo")/SUMIFS('Data Cruda'!$K$2:$K$1801,'Data Cruda'!$A$2:$A$1801,2021,'Data Cruda'!$C$2:$C$1801,"Mayo"),0) -> 0.15012544 | G28: =IFERROR(SUMIFS('Data Cruda'!$P$2:$P$1801,'Data Cruda'!$A$2:$A$1801,2021,'Data Cruda'!$C$2:$C$1801,"Junio")/SUMIFS('Data Cruda'!$K$2:$K$1801,'Data Cruda'!$A$2:$A$1801,2021,'Data Cruda'!$C$2:$C$1801,"Junio"),0) -> 0.16229559 | H28: =IFERROR(SUMIFS('Data Cruda'!$P$2:$P$1801,'Data Cruda'!$A$2:$A$1801,2021,'Data Cruda'!$C$2:$C$1801,"Julio")/SUMIFS('Data Cruda'!$K$2:$K$1801,'Data Cruda'!$A$2:$A$1801,2021,'Data Cruda'!$C$2:$C$1801,"Julio"),0) -> 0.16966511 | I28: =IFERROR(SUMIFS('Data Cruda'!$P$2:$P$1801,'Data Cruda'!$A$2:$A$1801,2021,'Data Cruda'!$C$2:$C$1801,"Agosto")/SUMIFS('Data Cruda'!$K$2:$K$1801,'Data Cruda'!$A$2:$A$1801,2021,'Data Cruda'!$C$2:$C$1801,"Agosto"),0) -> 0 | J28: =IFERROR(SUMIFS('Data Cruda'!$P$2:$P$1801,'Data Cruda'!$A$2:$A$1801,2021,'Data Cruda'!$C$2:$C$1801,"Setiembre")/SUMIFS('Data Cruda'!$K$2:$K$1801,'Data Cruda'!$A$2:$A$1801,2021,'Data Cruda'!$C$2:$C$1801,"Setiembre"),0) -> 0.15984318 | K28: =IFERROR(SUMIFS('Data Cruda'!$P$2:$P$1801,'Data Cruda'!$A$2:$A$1801,2021,'Data Cruda'!$C$2:$C$1801,"Octubre")/SUMIFS('Data Cruda'!$K$2:$K$1801,'Data Cruda'!$A$2:$A$1801,2021,'Data Cruda'!$C$2:$C$1801,"Octubre"),0) -> 0.15817888 | L28: =IFERROR(SUMIFS('Data Cruda'!$P$2:$P$1801,'Data Cruda'!$A$2:$A$1801,2021,'Data Cruda'!$C$2:$C$1801,"Noviembre")/SUMIFS('Data Cruda'!$K$2:$K$1801,'Data Cruda'!$A$2:$A$1801,2021,'Data Cruda'!$C$2:$C$1801,"Noviembre"),0) -> 0.187156 | M28: =IFERROR(SUMIFS('Data Cruda'!$P$2:$P$1801,'Data Cruda'!$A$2:$A$1801,2021,'Data Cruda'!$C$2:$C$1801,"Diciembre")/SUMIFS('Data Cruda'!$K$2:$K$1801,'Data Cruda'!$A$2:$A$1801,2021,'Data Cruda'!$C$2:$C$1801,"Diciembre"),0) -> 0.155128 | N28: =IFERROR(SUMIFS('Data Cruda'!$P$2:$P$1801,'Data Cruda'!$A$2:$A$1801,2021)/SUMIFS('Data Cruda'!$K$2:$K$1801,'Data Cruda'!$A$2:$A$1801,2021),0) -> 0.13432209
A29: Acum. | B29: =IFERROR(SUMPRODUCT(('Data Cruda'!$A$2:$A$1801=2021)*ISNUMBER(MATCH('Data Cruda'!$C$2:$C$1801,{"Enero"},0))*'Data Cruda'!$P$2:$P$1801)/SUMPRODUCT(('Data Cruda'!$A$2:$A$1801=2021)*ISNUMBER(MATCH('Data Cruda'!$C$2:$C$1801,{"Enero"},0))*'Data Cruda'!$K$2:$K$1801),0) -> 0.15808456 | C29: =IFERROR(SUMPRODUCT(('Data Cruda'!$A$2:$A$1801=2021)*ISNUMBER(MATCH('Data Cruda'!$C$2:$C$1801,{"Enero","Febrero"},0))*'Data Cruda'!$P$2:$P$1801)/SUMPRODUCT(('Data Cruda'!$A$2:$A$1801=2021)*ISNUMBER(MATCH('Data Cruda'!$C$2:$C$1801,{"Enero","Febrero"},0))*'Data Cruda'!$K$2:$K$1801),0) -> 0.1423274 | D29: =IFERROR(SUMPRODUCT(('Data Cruda'!$A$2:$A$1801=2021)*ISNUMBER(MATCH('Data Cruda'!$C$2:$C$1801,{"Enero","Febrero","Marzo"},0))*'Data Cruda'!$P$2:$P$1801)/SUMPRODUCT(('Data Cruda'!$A$2:$A$1801=2021)*ISNUMBER(MATCH('Data Cruda'!$C$2:$C$1801,{"Enero","Febrero","Marzo"},0))*'Data Cruda'!$K$2:$K$1801),0) -> 0.15096294 | E29: =IFERROR(SUMPRODUCT(('Data Cruda'!$A$2:$A$1801=2021)*ISNUMBER(MATCH('Data Cruda'!$C$2:$C$1801,{"Enero","Febrero","Marzo","Abril"},0))*'Data Cruda'!$P$2:$P$1801)/SUMPRODUCT(('Data Cruda'!$A$2:$A$1801=2021)*ISNUMBER(MATCH('Data Cruda'!$C$2:$C$1801,{"Enero","Febrero","Marzo","Abril"},0))*'Data Cruda'!$K$2:$K$1801),0) -> 0.10095252 | F29: =IFERROR(SUMPRODUCT(('Data Cruda'!$A$2:$A$1801=2021)*ISNUMBER(MATCH('Data Cruda'!$C$2:$C$1801,{"Enero","Febrero","Marzo","Abril","Mayo"},0))*'Data Cruda'!$P$2:$P$1801)/SUMPRODUCT(('Data Cruda'!$A$2:$A$1801=2021)*ISNUMBER(MATCH('Data Cruda'!$C$2:$C$1801,{"Enero","Febrero","Marzo","Abril","Mayo"},0))*'Data Cruda'!$K$2:$K$1801),0) -> 0.11529283 | G29: =IFERROR(SUMPRODUCT(('Data Cruda'!$A$2:$A$1801=2021)*ISNUMBER(MATCH('Data Cruda'!$C$2:$C$1801,{"Enero","Febrero","Marzo","Abril","Mayo","Junio"},0))*'Data Cruda'!$P$2:$P$1801)/SUMPRODUCT(('Data Cruda'!$A$2:$A$1801=2021)*ISNUMBER(MATCH('Data Cruda'!$C$2:$C$1801,{"Enero","Febrero","Marzo","Abril","Mayo","Junio"},0))*'Data Cruda'!$K$2:$K$1801),0) -> 0.12914486 | H29: =IFERROR(SUMPRODUCT(('Data Cruda'!$A$2:$A$1801=2021)*ISNUMBER(MATCH('Data Cruda'!$C$2:$C$1801,{"Enero","Febrero","Marzo","Abril","Mayo","Junio","Julio"},0))*'Data Cruda'!$P$2:$P$1801)/SUMPRODUCT(('Data Cruda'!$A$2:$A$1801=2021)*ISNUMBER(MATCH('Data Cruda'!$C$2:$C$1801,{"Enero","Febrero","Marzo","Abril","Mayo","Junio","Julio"},0))*'Data Cruda'!$K$2:$K$1801),0) -> 0.13465582 | I29: =IFERROR(SUMPRODUCT(('Data Cruda'!$A$2:$A$1801=2021)*ISNUMBER(MATCH('Data Cruda'!$C$2:$C$1801,{"Enero","Febrero","Marzo","Abril","Mayo","Junio","Julio","Agosto"},0))*'Data Cruda'!$P$2:$P$1801)/SUMPRODUCT(('Data Cruda'!$A$2:$A$1801=2021)*ISNUMBER(MATCH('Data Cruda'!$C$2:$C$1801,{"Enero","Febrero","Marzo","Abril","Mayo","Junio","Julio","Agosto"},0))*'Data Cruda'!$K$2:$K$1801),0) -> 0.12457901 | J29: =IFERROR(SUMPRODUCT(('Data Cruda'!$A$2:$A$1801=2021)*ISNUMBER(MATCH('Data Cruda'!$C$2:$C$1801,{"Enero","Febrero","Marzo","Abril","Mayo","Junio","Julio","Agosto","Setiembre"},0))*'Data Cruda'!$P$2:$P$1801)/SUMPRODUCT(('Data Cruda'!$A$2:$A$1801=2021)*ISNUMBER(MATCH('Data Cruda'!$C$2:$C$1801,{"Enero","Febrero","Marzo","Abril","Mayo","Junio","Julio","Agosto","Setiembre"},0))*'Data Cruda'!$K$2:$K$1801),0) -> 0.12730399 | K29: =IFERROR(SUMPRODUCT(('Data Cruda'!$A$2:$A$1801=2021)*ISNUMBER(MATCH('Data Cruda'!$C$2:$C$1801,{"Enero","Febrero","Marzo","Abril","Mayo","Junio","Julio","Agosto","Setiembre","Octubre"},0))*'Data Cruda'!$P$2:$P$1801)/SUMPRODUCT(('Data Cruda'!$A$2:$A$1801=2021)*ISNUMBER(MATCH('Data Cruda'!$C$2:$C$1801,{"Enero","Febrero","Marzo","Abril","Mayo","Junio","Julio","Agosto","Setiembre","Octubre"},0))*'Data Cruda'!$K$2:$K$1801),0) -> 0.12736743 | L29: =IFERROR(SUMPRODUCT(('Data Cruda'!$A$2:$A$1801=2021)*ISNUMBER(MATCH('Data Cruda'!$C$2:$C$1801,{"Enero","Febrero","Marzo","Abril","Mayo","Junio","Julio","Agosto","Setiembre","Octubre","Noviembre"},0))*'Data Cruda'!$P$2:$P$1801)/SUMPRODUCT(('Data Cruda'!$A$2:$A$1801=2021)*ISNUMBER(MATCH('Data Cruda'!$C$2:$C$1801,{"Enero","Febrero","Marzo","Abril","Mayo","Junio","Julio","Agosto","Setiembre","Octubre","Noviembre"},0))*'Data Cruda'!$K$2:$K$1801),0) -> 0.13124699 | M29: =IFERROR(SUMPRODUCT(('Data Cruda'!$A$2:$A$1801=2021)*ISNUMBER(MATCH('Data Cruda'!$C$2:$C$1801,{"Enero","Febrero","Marzo","Abril","Mayo","Junio","Julio","Agosto","Setiembre","Octubre","Noviembre","Diciembre"},0))*'Data Cruda'!$P$2:$P$1801)/SUMPRODUCT(('Data Cruda'!$A$2:$A$1801=2021)*ISNUMBER(MATCH('Data Cruda'!$C$2:$C$1801,{"Enero","Febrero","Marzo","Abril","Mayo","Junio","Julio","Agosto","Setiembre","Octubre","Noviembre","Diciembre"},0))*'Data Cruda'!$K$2:$K$1801),0) -> 0.13432209 | N29: =N28 -> 0.13432209
A31: 2022 | B31: =IFERROR(SUMIFS('Data Cruda'!$P$2:$P$1801,'Data Cruda'!$A$2:$A$1801,2022,'Data Cruda'!$C$2:$C$1801,"Enero")/SUMIFS('Data Cruda'!$K$2:$K$1801,'Data Cruda'!$A$2:$A$1801,2022,'Data Cruda'!$C$2:$C$1801,"Enero"),0) -> 0.14979527 | C31: =IFERROR(SUMIFS('Data Cruda'!$P$2:$P$1801,'Data Cruda'!$A$2:$A$1801,2022,'Data Cruda'!$C$2:$C$1801,"Febrero")/SUMIFS('Data Cruda'!$K$2:$K$1801,'Data Cruda'!$A$2:$A$1801,2022,'Data Cruda'!$C$2:$C$1801,"Febrero"),0) -> 0.13670559 | D31: =IFERROR(SUMIFS('Data Cruda'!$P$2:$P$1801,'Data Cruda'!$A$2:$A$1801,2022,'Data Cruda'!$C$2:$C$1801,"Marzo")/SUMIFS('Data Cruda'!$K$2:$K$1801,'Data Cruda'!$A$2:$A$1801,2022,'Data Cruda'!$C$2:$C$1801,"Marzo"),0) -> 0.16291328 | E31: =IFERROR(SUMIFS('Data Cruda'!$P$2:$P$1801,'Data Cruda'!$A$2:$A$1801,2022,'Data Cruda'!$C$2:$C$1801,"Abril")/SUMIFS('Data Cruda'!$K$2:$K$1801,'Data Cruda'!$A$2:$A$1801,2022,'Data Cruda'!$C$2:$C$1801,"Abril"),0) -> 0.053779133 | F31: =IFERROR(SUMIFS('Data Cruda'!$P$2:$P$1801,'Data Cruda'!$A$2:$A$1801,2022,'Data Cruda'!$C$2:$C$1801,"Mayo")/SUMIFS('Data Cruda'!$K$2:$K$1801,'Data Cruda'!$A$2:$A$1801,2022,'Data Cruda'!$C$2:$C$1801,"Mayo"),0) -> 0.17489223 | G31: =IFERROR(SUMIFS('Data Cruda'!$P$2:$P$1801,'Data Cruda'!$A$2:$A$1801,2022,'Data Cruda'!$C$2:$C$1801,"Junio")/SUMIFS('Data Cruda'!$K$2:$K$1801,'Data Cruda'!$A$2:$A$1801,2022,'Data Cruda'!$C$2:$C$1801,"Junio"),0) -> 0.16972186 | H31: =IFERROR(SUMIFS('Data Cruda'!$P$2:$P$1801,'Data Cruda'!$A$2:$A$1801,2022,'Data Cruda'!$C$2:$C$1801,"Julio")/SUMIFS('Data Cruda'!$K$2:$K$1801,'Data Cruda'!$A$2:$A$1801,2022,'Data Cruda'!$C$2:$C$1801,"Julio"),0) -> 0.16683669 | I31: =IFERROR(SUMIFS('Data Cruda'!$P$2:$P$1801,'Data Cruda'!$A$2:$A$1801,2022,'Data Cruda'!$C$2:$C$1801,"Agosto")/SUMIFS('Data Cruda'!$K$2:$K$1801,'Data Cruda'!$A$2:$A$1801,2022,'Data Cruda'!$C$2:$C$1801,"Agosto"),0) -> 0.14879388 | J31: =IFERROR(SUMIFS('Data Cruda'!$P$2:$P$1801,'Data Cruda'!$A$2:$A$1801,2022,'Data Cruda'!$C$2:$C$1801,"Setiembre")/SUMIFS('Data Cruda'!$K$2:$K$1801,'Data Cruda'!$A$2:$A$1801,2022,'Data Cruda'!$C$2:$C$1801,"Setiembre"),0) -> 0.24212895 | K31: =IFERROR(SUMIFS('Data Cruda'!$P$2:$P$1801,'Data Cruda'!$A$2:$A$1801,2022,'Data Cruda'!$C$2:$C$1801,"Octubre")/SUMIFS('Data Cruda'!$K$2:$K$1801,'Data Cruda'!$A$2:$A$1801,2022,'Data Cruda'!$C$2:$C$1801,"Octubre"),0) -> 0.15487694 | L31: =IFERROR(SUMIFS('Data Cruda'!$P$2:$P$1801,'Data Cruda'!$A$2:$A$1801,2022,'Data Cruda'!$C$2:$C$1801,"Noviembre")/SUMIFS('Data Cruda'!$K$2:$K$1801,'Data Cruda'!$A$2:$A$1801,2022,'Data Cruda'!$C$2:$C$1801,"Noviembre"),0) -> 0.15650922 | M31: =IFERROR(SUMIFS('Data Cruda'!$P$2:$P$1801,'Data Cruda'!$A$2:$A$1801,2022,'Data Cruda'!$C$2:$C$1801,"Diciembre")/SUMIFS('Data Cruda'!$K$2:$K$1801,'Data Cruda'!$A$2:$A$1801,2022,'Data Cruda'!$C$2:$C$1801,"Diciembre"),0) -> 0.14372703 | N31: =IFERROR(SUMIFS('Data Cruda'!$P$2:$P$1801,'Data Cruda'!$A$2:$A$1801,2022)/SUMIFS('Data Cruda'!$K$2:$K$1801,'Data Cruda'!$A$2:$A$1801,2022),0) -> 0.14102208
A32: Acum. | B32: =IFERROR(SUMPRODUCT(('Data Cruda'!$A$2:$A$1801=2022)*ISNUMBER(MATCH('Data Cruda'!$C$2:$C$1801,{"Enero"},0))*'Data Cruda'!$P$2:$P$1801)/SUMPRODUCT(('Data Cruda'!$A$2:$A$1801=2022)*ISNUMBER(MATCH('Data Cruda'!$C$2:$C$1801,{"Enero"},0))*'Data Cruda'!$K$2:$K$1801),0) -> 0.14979527 | C32: =IFERROR(SUMPRODUCT(('Data Cruda'!$A$2:$A$1801=2022)*ISNUMBER(MATCH('Data Cruda'!$C$2:$C$1801,{"Enero","Febrero"},0))*'Data Cruda'!$P$2:$P$1801)/SUMPRODUCT(('Data Cruda'!$A$2:$A$1801=2022)*ISNUMBER(MATCH('Data Cruda'!$C$2:$C$1801,{"Enero","Febrero"},0))*'Data Cruda'!$K$2:$K$1801),0) -> 0.13743883 | D32: =IFERROR(SUMPRODUCT(('Data Cruda'!$A$2:$A$1801=2022)*ISNUMBER(MATCH('Data Cruda'!$C$2:$C$1801,{"Enero","Febrero","Marzo"},0))*'Data Cruda'!$P$2:$P$1801)/SUMPRODUCT(('Data Cruda'!$A$2:$A$1801=2022)*ISNUMBER(MATCH('Data Cruda'!$C$2:$C$1801,{"Enero","Febrero","Marzo"},0))*'Data Cruda'!$K$2:$K$1801),0) -> 0.14935023 | E32: =IFERROR(SUMPRODUCT(('Data Cruda'!$A$2:$A$1801=2022)*ISNUMBER(MATCH('Data Cruda'!$C$2:$C$1801,{"Enero","Febrero","Marzo","Abril"},0))*'Data Cruda'!$P$2:$P$1801)/SUMPRODUCT(('Data Cruda'!$A$2:$A$1801=2022)*ISNUMBER(MATCH('Data Cruda'!$C$2:$C$1801,{"Enero","Febrero","Marzo","Abril"},0))*'Data Cruda'!$K$2:$K$1801),0) -> 0.10661663 | F32: =IFERROR(SUMPRODUCT(('Data Cruda'!$A$2:$A$1801=2022)*ISNUMBER(MATCH('Data Cruda'!$C$2:$C$1801,{"Enero","Febrero","Marzo","Abril","Mayo"},0))*'Data Cruda'!$P$2:$P$1801)/SUMPRODUCT(('Data Cruda'!$A$2:$A$1801=2022)*ISNUMBER(MATCH('Data Cruda'!$C$2:$C$1801,{"Enero","Febrero","Marzo","Abril","Mayo"},0))*'Data Cruda'!$K$2:$K$1801),0) -> 0.12523099 | G32: =IFERROR(SUMPRODUCT(('Data Cruda'!$A$2:$A$1801=2022)*ISNUMBER(MATCH('Data Cruda'!$C$2:$C$1801,{"Enero","Febrero","Marzo","Abril","Mayo","Junio"},0))*'Data Cruda'!$P$2:$P$1801)/SUMPRODUCT(('Data Cruda'!$A$2:$A$1801=2022)*ISNUMBER(MATCH('Data Cruda'!$C$2:$C$1801,{"Enero","Febrero","Marzo","Abril","Mayo","Junio"},0))*'Data Cruda'!$K$2:$K$1801),0) -> 0.12831691 | H32: =IFERROR(SUMPRODUCT(('Data Cruda'!$A$2:$A$1801=2022)*ISNUMBER(MATCH('Data Cruda'!$C$2:$C$1801,{"Enero","Febrero","Marzo","Abril","Mayo","Junio","Julio"},0))*'Data Cruda'!$P$2:$P$1801)/SUMPRODUCT(('Data Cruda'!$A$2:$A$1801=2022)*ISNUMBER(MATCH('Data Cruda'!$C$2:$C$1801,{"Enero","Febrero","Marzo","Abril","Mayo","Junio","Julio"},0))*'Data Cruda'!$K$2:$K$1801),0) -> 0.13388235 | I32: =IFERROR(SUMPRODUCT(('Data Cruda'!$A$2:$A$1801=2022)*ISNUMBER(MATCH('Data Cruda'!$C$2:$C$1801,{"Enero","Febrero","Marzo","Abril","Mayo","Junio","Julio","Agosto"},0))*'Data Cruda'!$P$2:$P$1801)/SUMPRODUCT(('Data Cruda'!$A$2:$A$1801=2022)*ISNUMBER(MATCH('Data Cruda'!$C$2:$C$1801,{"Enero","Febrero","Marzo","Abril","Mayo","Junio","Julio","Agosto"},0))*'Data Cruda'!$K$2:$K$1801),0) -> 0.13495778 | J32: =IFERROR(SUMPRODUCT(('Data Cruda'!$A$2:$A$1801=2022)*ISNUMBER(MATCH('Data Cruda'!$C$2:$C$1801,{"Enero","Febrero","Marzo","Abril","Mayo","Junio","Julio","Agosto","Setiembre"},0))*'Data Cruda'!$P$2:$P$1801)/SUMPRODUCT(('Data Cruda'!$A$2:$A$1801=2022)*ISNUMBER(MATCH('Data Cruda'!$C$2:$C$1801,{"Enero","Febrero","Marzo","Abril","Mayo","Junio","Julio","Agosto","Setiembre"},0))*'Data Cruda'!$K$2:$K$1801),0) -> 0.13974545 | K32: =IFERROR(SUMPRODUCT(('Data Cruda'!$A$2:$A$1801=2022)*ISNUMBER(MATCH('Data Cruda'!$C$2:$C$1801,{"Enero","Febrero","Marzo","Abril","Mayo","Junio","Julio","Agosto","Setiembre","Octubre"},0))*'Data Cruda'!$P$2:$P$1801)/SUMPRODUCT(('Data Cruda'!$A$2:$A$1801=2022)*ISNUMBER(MATCH('Data Cruda'!$C$2:$C$1801,{"Enero","Febrero","Marzo","Abril","Mayo","Junio","Julio","Agosto","Setiembre","Octubre"},0))*'Data Cruda'!$K$2:$K$1801),0) -> 0.13982436 | L32: =IFERROR(SUMPRODUCT(('Data Cruda'!$A$2:$A$1801=2022)*ISNUMBER(MATCH('Data Cruda'!$C$2:$C$1801,{"Enero","Febrero","Marzo","Abril","Mayo","Junio","Julio","Agosto","Setiembre","Octubre","Noviembre"},0))*'Data Cruda'!$P$2:$P$1801)/SUMPRODUCT(('Data Cruda'!$A$2:$A$1801=2022)*ISNUMBER(MATCH('Data Cruda'!$C$2:$C$1801,{"Enero","Febrero","Marzo","Abril","Mayo","Junio","Julio","Agosto","Setiembre","Octubre","Noviembre"},0))*'Data Cruda'!$K$2:$K$1801),0) -> 0.14058617 | M32: =IFERROR(SUMPRODUCT(('Data Cruda'!$A$2:$A$1801=2022)*ISNUMBER(MATCH('Data Cruda'!$C$2:$C$1801,{"Enero","Febrero","Marzo","Abril","Mayo","Junio","Julio","Agosto","Setiembre","Octubre","Noviembre","Diciembre"},0))*'Data Cruda'!$P$2:$P$1801)/SUMPRODUCT(('Data Cruda'!$A$2:$A$1801=2022)*ISNUMBER(MATCH('Data Cruda'!$C$2:$C$1801,{"Enero","Febrero","Marzo","Abril","Mayo","Junio","Julio","Agosto","Setiembre","Octubre","Noviembre","Diciembre"},0))*'Data Cruda'!$K$2:$K$1801),0) -> 0.14102208 | N32: =N31 -> 0.14102208
A34: 2023 | B34: =IFERROR(SUMIFS('Data Cruda'!$P$2:$P$1801,'Data Cruda'!$A$2:$A$1801,2023,'Data Cruda'!$C$2:$C$1801,"Enero")/SUMIFS('Data Cruda'!$K$2:$K$1801,'Data Cruda'!$A$2:$A$1801,2023,'Data Cruda'!$C$2:$C$1801,"Enero"),0) -> 0.17726918 | C34: =IFERROR(SUMIFS('Data Cruda'!$P$2:$P$1801,'Data Cruda'!$A$2:$A$1801,2023,'Data Cruda'!$C$2:$C$1801,"Febrero")/SUMIFS('Data Cruda'!$K$2:$K$1801,'Data Cruda'!$A$2:$A$1801,2023,'Data Cruda'!$C$2:$C$1801,"Febrero"),0) -> 0.17837702 | D34: =IFERROR(SUMIFS('Data Cruda'!$P$2:$P$1801,'Data Cruda'!$A$2:$A$1801,2023,'Data Cruda'!$C$2:$C$1801,"Marzo")/SUMIFS('Data Cruda'!$K$2:$K$1801,'Data Cruda'!$A$2:$A$1801,2023,'Data Cruda'!$C$2:$C$1801,"Marzo"),0) -> 0.14069184 | E34: =IFERROR(SUMIFS('Data Cruda'!$P$2:$P$1801,'Data Cruda'!$A$2:$A$1801,2023,'Data Cruda'!$C$2:$C$1801,"Abril")/SUMIFS('Data Cruda'!$K$2:$K$1801,'Data Cruda'!$A$2:$A$1801,2023,'Data Cruda'!$C$2:$C$1801,"Abril"),0) -> 0.19030853 | F34: =IFERROR(SUMIFS('Data Cruda'!$P$2:$P$1801,'Data Cruda'!$A$2:$A$1801,2023,'Data Cruda'!$C$2:$C$1801,"Mayo")/SUMIFS('Data Cruda'!$K$2:$K$1801,'Data Cruda'!$A$2:$A$1801,2023,'Data Cruda'!$C$2:$C$1801,"Mayo"),0) -> 0.19930511 | G34: =IFERROR(SUMIFS('Data Cruda'!$P$2:$P$1801,'Data Cruda'!$A$2:$A$1801,2023,'Data Cruda'!$C$2:$C$1801,"Junio")/SUMIFS('Data Cruda'!$K$2:$K$1801,'Data Cruda'!$A$2:$A$1801,2023,'Data Cruda'!$C$2:$C$1801,"Junio"),0) -> 0.16235663 | H34: =IFERROR(SUMIFS('Data Cruda'!$P$2:$P$1801,'Data Cruda'!$A$2:$A$1801,2023,'Data Cruda'!$C$2:$C$1801,"Julio")/SUMIFS('Data Cruda'!$K$2:$K$1801,'Data Cruda'!$A$2:$A$1801,2023,'Data Cruda'!$C$2:$C$1801,"Julio"),0) -> 0.17336865 | I34: =IFERROR(SUMIFS('Data Cruda'!$P$2:$P$1801,'Data Cruda'!$A$2:$A$1801,2023,'Data Cruda'!$C$2:$C$1801,"Agosto")/SUMIFS('Data Cruda'!$K$2:$K$1801,'Data Cruda'!$A$2:$A$1801,2023,'Data Cruda'!$C$2:$C$1801,"Agosto"),0) -> 0.18420635 | J34: =IFERROR(SUMIFS('Data Cruda'!$P$2:$P$1801,'Data Cruda'!$A$2:$A$1801,2023,'Data Cruda'!$C$2:$C$1801,"Setiembre")/SUMIFS('Data Cruda'!$K$2:$K$1801,'Data Cruda'!$A$2:$A$1801,2023,'Data Cruda'!$C$2:$C$1801,"Setiembre"),0) -> 0.10725931 | K34: =IFERROR(SUMIFS('Data Cruda'!$P$2:$P$1801,'Data Cruda'!$A$2:$A$1801,2023,'Data Cruda'!$C$2:$C$1801,"Octubre")/SUMIFS('Data Cruda'!$K$2:$K$1801,'Data Cruda'!$A$2:$A$1801,2023,'Data Cruda'!$C$2:$C$1801,"Octubre"),0) -> 0.15440088 | L34: =IFERROR(SUMIFS('Data Cruda'!$P$2:$P$1801,'Data Cruda'!$A$2:$A$1801,2023,'Data Cruda'!$C$2:$C$1801,"Noviembre")/SUMIFS('Data Cruda'!$K$2:$K$1801,'Data Cruda'!$A$2:$A$1801,2023,'Data Cruda'!$C$2:$C$1801,"Noviembre"),0) -> 0.1202607 | M34: =IFERROR(SUMIFS('Data Cruda'!$P$2:$P$1801,'Data Cruda'!$A$2:$A$1801,2023,'Data Cruda'!$C$2:$C$1801,"Diciembre")/SUMIFS('Data Cruda'!$K$2:$K$1801,'Data Cruda'!$A$2:$A$1801,2023,'Data Cruda'!$C$2:$C$1801,"Diciembre"),0) -> 0.18743318 | N34: =IFERROR(SUMIFS('Data Cruda'!$P$2:$P$1801,'Data Cruda'!$A$2:$A$1801,2023)/SUMIFS('Data Cruda'!$K$2:$K$1801,'Data Cruda'!$A$2:$A$1801,2023),0) -> 0.17091729
A35: Acum. | B35: =IFERROR(SUMPRODUCT(('Data Cruda'!$A$2:$A$1801=2023)*ISNUMBER(MATCH('Data Cruda'!$C$2:$C$1801,{"Enero"},0))*'Data Cruda'!$P$2:$P$1801)/SUMPRODUCT(('Data Cruda'!$A$2:$A$1801=2023)*ISNUMBER(MATCH('Data Cruda'!$C$2:$C$1801,{"Enero"},0))*'Data Cruda'!$K$2:$K$1801),0) -> 0.17726918 | C35: =IFERROR(SUMPRODUCT(('Data Cruda'!$A$2:$A$1801=2023)*ISNUMBER(MATCH('Data Cruda'!$C$2:$C$1801,{"Enero","Febrero"},0))*'Data Cruda'!$P$2:$P$1801)/SUMPRODUCT(('Data Cruda'!$A$2:$A$1801=2023)*ISNUMBER(MATCH('Data Cruda'!$C$2:$C$1801,{"Enero","Febrero"},0))*'Data Cruda'!$K$2:$K$1801),0) -> 0.17775019 | D35: =IFERROR(SUMPRODUCT(('Data Cruda'!$A$2:$A$1801=2023)*ISNUMBER(MATCH('Data Cruda'!$C$2:$C$1801,{"Enero","Febrero","Marzo"},0))*'Data Cruda'!$P$2:$P$1801)/SUMPRODUCT(('Data Cruda'!$A$2:$A$1801=2023)*ISNUMBER(MATCH('Data Cruda'!$C$2:$C$1801,{"Enero","Febrero","Marzo"},0))*'Data Cruda'!$K$2:$K$1801),0) -> 0.15293708 | E35: =IFERROR(SUMPRODUCT(('Data Cruda'!$A$2:$A$1801=2023)*ISNUMBER(MATCH('Data Cruda'!$C$2:$C$1801,{"Enero","Febrero","Marzo","Abril"},0))*'Data Cruda'!$P$2:$P$1801)/SUMPRODUCT(('Data Cruda'!$A$2:$A$1801=2023)*ISNUMBER(MATCH('Data Cruda'!$C$2:$C$1801,{"Enero","Febrero","Marzo","Abril"},0))*'Data Cruda'!$K$2:$K$1801),0) -> 0.16506373 | F35: =IFERROR(SUMPRODUCT(('Data Cruda'!$A$2:$A$1801=2023)*ISNUMBER(MATCH('Data Cruda'!$C$2:$C$1801,{"Enero","Febrero","Marzo","Abril","Mayo"},0))*'Data Cruda'!$P$2:$P$1801)/SUMPRODUCT(('Data Cruda'!$A$2:$A$1801=2023)*ISNUMBER(MATCH('Data Cruda'!$C$2:$C$1801,{"Enero","Febrero","Marzo","Abril","Mayo"},0))*'Data Cruda'!$K$2:$K$1801),0) -> 0.17677702 | G35: =IFERROR(SUMPRODUCT(('Data Cruda'!$A$2:$A$1801=2023)*ISNUMBER(MATCH('Data Cruda'!$C$2:$C$1801,{"Enero","Febrero","Marzo","Abril","Mayo","Junio"},0))*'Data Cruda'!$P$2:$P$1801)/SUMPRODUCT(('Data Cruda'!$A$2:$A$1801=2023)*ISNUMBER(MATCH('Data Cruda'!$C$2:$C$1801,{"Enero","Febrero","Marzo","Abril","Mayo","Junio"},0))*'Data Cruda'!$K$2:$K$1801),0) -> 0.17520222 | H35: =IFERROR(SUMPRODUCT(('Data Cruda'!$A$2:$A$1801=2023)*ISNUMBER(MATCH('Data Cruda'!$C$2:$C$1801,{"Enero","Febrero","Marzo","Abril","Mayo","Junio","Julio"},0))*'Data Cruda'!$P$2:$P$1801)/SUMPRODUCT(('Data Cruda'!$A$2:$A$1801=2023)*ISNUMBER(MATCH('Data Cruda'!$C$2:$C$1801,{"Enero","Febrero","Marzo","Abril","Mayo","Junio","Julio"},0))*'Data Cruda'!$K$2:$K$1801),0) -> 0.17494205 | I35: =IFERROR(SUMPRODUCT(('Data Cruda'!$A$2:$A$1801=2023)*ISNUMBER(MATCH('Data Cruda'!$C$2:$C$1801,{"Enero","Febrero","Marzo","Abril","Mayo","Junio","Julio","Agosto"},0))*'Data Cruda'!$P$2:$P$1801)/SUMPRODUCT(('Data Cruda'!$A$2:$A$1801=2023)*ISNUMBER(MATCH('Data Cruda'!$C$2:$C$1801,{"Enero","Febrero","Marzo","Abril","Mayo","Junio","Julio","Agosto"},0))*'Data Cruda'!$K$2:$K$1801),0) -> 0.17576981 | J35: =IFERROR(SUMPRODUCT(('Data Cruda'!$A$2:$A$1801=2023)*ISNUMBER(MATCH('Data Cruda'!$C$2:$C$1801,{"Enero","Febrero","Marzo","Abril","Mayo","Junio","Julio","Agosto","Setiembre"},0))*'Data Cruda'!$P$2:$P$1801)/SUMPRODUCT(('Data Cruda'!$A$2:$A$1801=2023)*ISNUMBER(MATCH('Data Cruda'!$C$2:$C$1801,{"Enero","Febrero","Marzo","Abril","Mayo","Junio","Julio","Agosto","Setiembre"},0))*'Data Cruda'!$K$2:$K$1801),0) -> 0.17560667 | K35: =IFERROR(SUMPRODUCT(('Data Cruda'!$A$2:$A$1801=2023)*ISNUMBER(MATCH('Data Cruda'!$C$2:$C$1801,{"Enero","Febrero","Marzo","Abril","Mayo","Junio","Julio","Agosto","Setiembre","Octubre"},0))*'Data Cruda'!$P$2:$P$1801)/SUMPRODUCT(('Data Cruda'!$A$2:$A$1801=2023)*ISNUMBER(MATCH('Data Cruda'!$C$2:$C$1801,{"Enero","Febrero","Marzo","Abril","Mayo","Junio","Julio","Agosto","Setiembre","Octubre"},0))*'Data Cruda'!$K$2:$K$1801),0) -> 0.17457838 | L35: =IFERROR(SUMPRODUCT(('Data Cruda'!$A$2:$A$1801=2023)*ISNUMBER(MATCH('Data Cruda'!$C$2:$C$1801,{"Enero","Febrero","Marzo","Abril","Mayo","Junio","Julio","Agosto","Setiembre","Octubre","Noviembre"},0))*'Data Cruda'!$P$2:$P$1801)/SUMPRODUCT(('Data Cruda'!$A$2:$A$1801=2023)*ISNUMBER(MATCH('Data Cruda'!$C$2:$C$1801,{"Enero","Febrero","Marzo","Abril","Mayo","Junio","Julio","Agosto","Setiembre","Octubre","Noviembre"},0))*'Data Cruda'!$K$2:$K$1801),0) -> 0.16896435 | M35: =IFERROR(SUMPRODUCT(('Data Cruda'!$A$2:$A$1801=2023)*ISNUMBER(MATCH('Data Cruda'!$C$2:$C$1801,{"Enero","Febrero","Marzo","Abril","Mayo","Junio","Julio","Agosto","Setiembre","Octubre","Noviembre","Diciembre"},0))*'Data Cruda'!$P$2:$P$1801)/SUMPRODUCT(('Data Cruda'!$A$2:$A$1801=2023)*ISNUMBER(MATCH('Data Cruda'!$C$2:$C$1801,{"Enero","Febrero","Marzo","Abril","Mayo","Junio","Julio","Agosto","Setiembre","Octubre","Noviembre","Diciembre"},0))*'Data Cruda'!$K$2:$K$1801),0) -> 0.17091729 | N35: =N34 -> 0.17091729
A37: 2024 | B37: =IFERROR(SUMIFS('Data Cruda'!$P$2:$P$1801,'Data Cruda'!$A$2:$A$1801,2024,'Data Cruda'!$C$2:$C$1801,"Enero")/SUMIFS('Data Cruda'!$K$2:$K$1801,'Data Cruda'!$A$2:$A$1801,2024,'Data Cruda'!$C$2:$C$1801,"Enero"),0) -> 0.16666737 | C37: =IFERROR(SUMIFS('Data Cruda'!$P$2:$P$1801,'Data Cruda'!$A$2:$A$1801,2024,'Data Cruda'!$C$2:$C$1801,"Febrero")/SUMIFS('Data Cruda'!$K$2:$K$1801,'Data Cruda'!$A$2:$A$1801,2024,'Data Cruda'!$C$2:$C$1801,"Febrero"),0) -> 0.16398718 | D37: =IFERROR(SUMIFS('Data Cruda'!$P$2:$P$1801,'Data Cruda'!$A$2:$A$1801,2024,'Data Cruda'!$C$2:$C$1801,"Marzo")/SUMIFS('Data Cruda'!$K$2:$K$1801,'Data Cruda'!$A$2:$A$1801,2024,'Data Cruda'!$C$2:$C$1801,"Marzo"),0) -> 0.14997408 | E37: =IFERROR(SUMIFS('Data Cruda'!$P$2:$P$1801,'Data Cruda'!$A$2:$A$1801,2024,'Data Cruda'!$C$2:$C$1801,"Abril")/SUMIFS('Data Cruda'!$K$2:$K$1801,'Data Cruda'!$A$2:$A$1801,2024,'Data Cruda'!$C$2:$C$1801,"Abril"),0) -> 0.14766614 | F37: =IFERROR(SUMIFS('Data Cruda'!$P$2:$P$1801,'Data Cruda'!$A$2:$A$1801,2024,'Data Cruda'!$C$2:$C$1801,"Mayo")/SUMIFS('Data Cruda'!$K$2:$K$1801,'Data Cruda'!$A$2:$A$1801,2024,'Data Cruda'!$C$2:$C$1801,"Mayo"),0) -> 0.16246946 | G37: =IFERROR(SUMIFS('Data Cruda'!$P$2:$P$1801,'Data Cruda'!$A$2:$A$1801,2024,'Data Cruda'!$C$2:$C$1801,"Junio")/SUMIFS('Data Cruda'!$K$2:$K$1801,'Data Cruda'!$A$2:$A$1801,2024,'Data Cruda'!$C$2:$C$1801,"Junio"),0) -> 0.18121366 | H37: =IFERROR(SUMIFS('Data Cruda'!$P$2:$P$1801,'Data Cruda'!$A$2:$A$1801,2024,'Data Cruda'!$C$2:$C$1801,"Julio")/SUMIFS('Data Cruda'!$K$2:$K$1801,'Data Cruda'!$A$2:$A$1801,2024,'Data Cruda'!$C$2:$C$1801,"Julio"),0) -> 0.1166396 | I37: =IFERROR(SUMIFS('Data Cruda'!$P$2:$P$1801,'Data Cruda'!$A$2:$A$1801,2024,'Data Cruda'!$C$2:$C$1801,"Agosto")/SUMIFS('Data Cruda'!$K$2:$K$1801,'Data Cruda'!$A$2:$A$1801,2024,'Data Cruda'!$C$2:$C$1801,"Agosto"),0) -> 0.14271307 | J37: =IFERROR(SUMIFS('Data Cruda'!$P$2:$P$1801,'Data Cruda'!$A$2:$A$1801,2024,'Data Cruda'!$C$2:$C$1801,"Setiembre")/SUMIFS('Data Cruda'!$K$2:$K$1801,'Data Cruda'!$A$2:$A$1801,2024,'Data Cruda'!$C$2:$C$1801,"Setiembre"),0) -> 0.15664275 | K37: =IFERROR(SUMIFS('Data Cruda'!$P$2:$P$1801,'Data Cruda'!$A$2:$A$1801,2024,'Data Cruda'!$C$2:$C$1801,"Octubre")/SUMIFS('Data Cruda'!$K$2:$K$1801,'Data Cruda'!$A$2:$A$1801,2024,'Data Cruda'!$C$2:$C$1801,"Octubre"),0) -> 0.14778752 | L37: =IFERROR(SUMIFS('Data Cruda'!$P$2:$P$1801,'Data Cruda'!$A$2:$A$1801,2024,'Data Cruda'!$C$2:$C$1801,"Noviembre")/SUMIFS('Data Cruda'!$K$2:$K$1801,'Data Cruda'!$A$2:$A$1801,2024,'Data Cruda'!$C$2:$C$1801,"Noviembre"),0) -> 0.18297841 | M37: =IFERROR(SUMIFS('Data Cruda'!$P$2:$P$1801,'Data Cruda'!$A$2:$A$1801,2024,'Data Cruda'!$C$2:$C$1801,"Diciembre")/SUMIFS('Data Cruda'!$K$2:$K$1801,'Data Cruda'!$A$2:$A$1801,2024,'Data Cruda'!$C$2:$C$1801,"Diciembre"),0) -> 0.14949483 | N37: =IFERROR(SUMIFS('Data Cruda'!$P$2:$P$1801,'Data Cruda'!$A$2:$A$1801,2024)/SUMIFS('Data Cruda'!$K$2:$K$1801,'Data Cruda'!$A$2:$A$1801,2024),0) -> 0.15300028
A38: Acum. | B38: =IFERROR(SUMPRODUCT(('Data Cruda'!$A$2:$A$1801=2024)*ISNUMBER(MATCH('Data Cruda'!$C$2:$C$1801,{"Enero"},0))*'Data Cruda'!$P$2:$P$1801)/SUMPRODUCT(('Data Cruda'!$A$2:$A$1801=2024)*ISNUMBER(MATCH('Data Cruda'!$C$2:$C$1801,{"Enero"},0))*'Data Cruda'!$K$2:$K$1801),0) -> 0.16666737 | C38: =IFERROR(SUMPRODUCT(('Data Cruda'!$A$2:$A$1801=2024)*ISNUMBER(MATCH('Data Cruda'!$C$2:$C$1801,{"Enero","Febrero"},0))*'Data Cruda'!$P$2:$P$1801)/SUMPRODUCT(('Data Cruda'!$A$2:$A$1801=2024)*ISNUMBER(MATCH('Data Cruda'!$C$2:$C$1801,{"Enero","Febrero"},0))*'Data Cruda'!$K$2:$K$1801),0) -> 0.1641529 | D38: =IFERROR(SUMPRODUCT(('Data Cruda'!$A$2:$A$1801=2024)*ISNUMBER(MATCH('Data Cruda'!$C$2:$C$1801,{"Enero","Febrero","Marzo"},0))*'Data Cruda'!$P$2:$P$1801)/SUMPRODUCT(('Data Cruda'!$A$2:$A$1801=2024)*ISNUMBER(MATCH('Data Cruda'!$C$2:$C$1801,{"Enero","Febrero","Marzo"},0))*'Data Cruda'!$K$2:$K$1801),0) -> 0.15362589 | E38: =IFERROR(SUMPRODUCT(('Data Cruda'!$A$2:$A$1801=2024)*ISNUMBER(MATCH('Data Cruda'!$C$2:$C$1801,{"Enero","Febrero","Marzo","Abril"},0))*'Data Cruda'!$P$2:$P$1801)/SUMPRODUCT(('Data Cruda'!$A$2:$A$1801=2024)*ISNUMBER(MATCH('Data Cruda'!$C$2:$C$1801,{"Enero","Febrero","Marzo","Abril"},0))*'Data Cruda'!$K$2:$K$1801),0) -> 0.15212576 | F38: =IFERROR(SUMPRODUCT(('Data Cruda'!$A$2:$A$1801=2024)*ISNUMBER(MATCH('Data Cruda'!$C$2:$C$1801,{"Enero","Febrero","Marzo","Abril","Mayo"},0))*'Data Cruda'!$P$2:$P$1801)/SUMPRODUCT(('Data Cruda'!$A$2:$A$1801=2024)*ISNUMBER(MATCH('Data Cruda'!$C$2:$C$1801,{"Enero","Febrero","Marzo","Abril","Mayo"},0))*'Data Cruda'!$K$2:$K$1801),0) -> 0.15549027 | G38: =IFERROR(SUMPRODUCT(('Data Cruda'!$A$2:$A$1801=2024)*ISNUMBER(MATCH('Data Cruda'!$C$2:$C$1801,{"Enero","Febrero","Marzo","Abril","Mayo","Junio"},0))*'Data Cruda'!$P$2:$P$1801)/SUMPRODUCT(('Data Cruda'!$A$2:$A$1801=2024)*ISNUMBER(MATCH('Data Cruda'!$C$2:$C$1801,{"Enero","Febrero","Marzo","Abril","Mayo","Junio"},0))*'Data Cruda'!$K$2:$K$1801),0) -> 0.15826206 | H38: =IFERROR(SUMPRODUCT(('Data Cruda'!$A$2:$A$1801=2024)*ISNUMBER(MATCH('Data Cruda'!$C$2:$C$1801,{"Enero","Febrero","Marzo","Abril","Mayo","Junio","Julio"},0))*'Data Cruda'!$P$2:$P$1801)/SUMPRODUCT(('Data Cruda'!$A$2:$A$1801=2024)*ISNUMBER(MATCH('Data Cruda'!$C$2:$C$1801,{"Enero","Febrero","Marzo","Abril","Mayo","Junio","Julio"},0))*'Data Cruda'!$K$2:$K$1801),0) -> 0.15297391 | I38: =IFERROR(SUMPRODUCT(('Data Cruda'!$A$2:$A$1801=2024)*ISNUMBER(MATCH('Data Cruda'!$C$2:$C$1801,{"Enero","Febrero","Marzo","Abril","Mayo","Junio","Julio","Agosto"},0))*'Data Cruda'!$P$2:$P$1801)/SUMPRODUCT(('Data Cruda'!$A$2:$A$1801=2024)*ISNUMBER(MATCH('Data Cruda'!$C$2:$C$1801,{"Enero","Febrero","Marzo","Abril","Mayo","Junio","Julio","Agosto"},0))*'Data Cruda'!$K$2:$K$1801),0) -> 0.15251287 | J38: =IFERROR(SUMPRODUCT(('Data Cruda'!$A$2:$A$1801=2024)*ISNUMBER(MATCH('Data Cruda'!$C$2:$C$1801,{"Enero","Febrero","Marzo","Abril","Mayo","Junio","Julio","Agosto","Setiembre"},0))*'Data Cruda'!$P$2:$P$1801)/SUMPRODUCT(('Data Cruda'!$A$2:$A$1801=2024)*ISNUMBER(MATCH('Data Cruda'!$C$2:$C$1801,{"Enero","Febrero","Marzo","Abril","Mayo","Junio","Julio","Agosto","Setiembre"},0))*'Data Cruda'!$K$2:$K$1801),0) -> 0.15261748 | K38: =IFERROR(SUMPRODUCT(('Data Cruda'!$A$2:$A$1801=2024)*ISNUMBER(MATCH('Data Cruda'!$C$2:$C$1801,{"Enero","Febrero","Marzo","Abril","Mayo","Junio","Julio","Agosto","Setiembre","Octubre"},0))*'Data Cruda'!$P$2:$P$1801)/SUMPRODUCT(('Data Cruda'!$A$2:$A$1801=2024)*ISNUMBER(MATCH('Data Cruda'!$C$2:$C$1801,{"Enero","Febrero","Marzo","Abril","Mayo","Junio","Julio","Agosto","Setiembre","Octubre"},0))*'Data Cruda'!$K$2:$K$1801),0) -> 0.15207483 | L38: =IFERROR(SUMPRODUCT(('Data Cruda'!$A$2:$A$1801=2024)*ISNUMBER(MATCH('Data Cruda'!$C$2:$C$1801,{"Enero","Febrero","Marzo","Abril","Mayo","Junio","Julio","Agosto","Setiembre","Octubre","Noviembre"},0))*'Data Cruda'!$P$2:$P$1801)/SUMPRODUCT(('Data Cruda'!$A$2:$A$1801=2024)*ISNUMBER(MATCH('Data Cruda'!$C$2:$C$1801,{"Enero","Febrero","Marzo","Abril","Mayo","Junio","Julio","Agosto","Setiembre","Octubre","Noviembre"},0))*'Data Cruda'!$K$2:$K$1801),0) -> 0.15302232 | M38: =IFERROR(SUMPRODUCT(('Data Cruda'!$A$2:$A$1801=2024)*ISNUMBER(MATCH('Data Cruda'!$C$2:$C$1801,{"Enero","Febrero","Marzo","Abril","Mayo","Junio","Julio","Agosto","Setiembre","Octubre","Noviembre","Diciembre"},0))*'Data Cruda'!$P$2:$P$1801)/SUMPRODUCT(('Data Cruda'!$A$2:$A$1801=2024)*ISNUMBER(MATCH('Data Cruda'!$C$2:$C$1801,{"Enero","Febrero","Marzo","Abril","Mayo","Junio","Julio","Agosto","Setiembre","Octubre","Noviembre","Diciembre"},0))*'Data Cruda'!$K$2:$K$1801),0) -> 0.15300028 | N38: =N37 -> 0.15300028
A40: 2025 | B40: =IFERROR(SUMIFS('Data Cruda'!$P$2:$P$1801,'Data Cruda'!$A$2:$A$1801,2025,'Data Cruda'!$C$2:$C$1801,"Enero")/SUMIFS('Data Cruda'!$K$2:$K$1801,'Data Cruda'!$A$2:$A$1801,2025,'Data Cruda'!$C$2:$C$1801,"Enero"),0) -> 0.15202929 | C40: =IFERROR(SUMIFS('Data Cruda'!$P$2:$P$1801,'Data Cruda'!$A$2:$A$1801,2025,'Data Cruda'!$C$2:$C$1801,"Febrero")/SUMIFS('Data Cruda'!$K$2:$K$1801,'Data Cruda'!$A$2:$A$1801,2025,'Data Cruda'!$C$2:$C$1801,"Febrero"),0) -> 0.15524631 | D40: =IFERROR(SUMIFS('Data Cruda'!$P$2:$P$1801,'Data Cruda'!$A$2:$A$1801,2025,'Data Cruda'!$C$2:$C$1801,"Marzo")/SUMIFS('Data Cruda'!$K$2:$K$1801,'Data Cruda'!$A$2:$A$1801,2025,'Data Cruda'!$C$2:$C$1801,"Marzo"),0) -> 0.15093029 | E40: =IFERROR(SUMIFS('Data Cruda'!$P$2:$P$1801,'Data Cruda'!$A$2:$A$1801,2025,'Data Cruda'!$C$2:$C$1801,"Abril")/SUMIFS('Data Cruda'!$K$2:$K$1801,'Data Cruda'!$A$2:$A$1801,2025,'Data Cruda'!$C$2:$C$1801,"Abril"),0) -> 0.17130529 | F40: =IFERROR(SUMIFS('Data Cruda'!$P$2:$P$1801,'Data Cruda'!$A$2:$A$1801,2025,'Data Cruda'!$C$2:$C$1801,"Mayo")/SUMIFS('Data Cruda'!$K$2:$K$1801,'Data Cruda'!$A$2:$A$1801,2025,'Data Cruda'!$C$2:$C$1801,"Mayo"),0) -> 0.16447295 | G40: =IFERROR(SUMIFS('Data Cruda'!$P$2:$P$1801,'Data Cruda'!$A$2:$A$1801,2025,'Data Cruda'!$C$2:$C$1801,"Junio")/SUMIFS('Data Cruda'!$K$2:$K$1801,'Data Cruda'!$A$2:$A$1801,2025,'Data Cruda'!$C$2:$C$1801,"Junio"),0) -> 0.14042711 | H40: =IFERROR(SUMIFS('Data Cruda'!$P$2:$P$1801,'Data Cruda'!$A$2:$A$1801,2025,'Data Cruda'!$C$2:$C$1801,"Julio")/SUMIFS('Data Cruda'!$K$2:$K$1801,'Data Cruda'!$A$2:$A$1801,2025,'Data Cruda'!$C$2:$C$1801,"Julio"),0) -> 0.14352754 | I40: =IFERROR(SUMIFS('Data Cruda'!$P$2:$P$1801,'Data Cruda'!$A$2:$A$1801,2025,'Data Cruda'!$C$2:$C$1801,"Agosto")/SUMIFS('Data Cruda'!$K$2:$K$1801,'Data Cruda'!$A$2:$A$1801,2025,'Data Cruda'!$C$2:$C$1801,"Agosto"),0) -> 0.17581193 | J40: =IFERROR(SUMIFS('Data Cruda'!$P$2:$P$1801,'Data Cruda'!$A$2:$A$1801,2025,'Data Cruda'!$C$2:$C$1801,"Setiembre")/SUMIFS('Data Cruda'!$K$2:$K$1801,'Data Cruda'!$A$2:$A$1801,2025,'Data Cruda'!$C$2:$C$1801,"Setiembre"),0) -> 0.16315694 | K40: =IFERROR(SUMIFS('Data Cruda'!$P$2:$P$1801,'Data Cruda'!$A$2:$A$1801,2025,'Data Cruda'!$C$2:$C$1801,"Octubre")/SUMIFS('Data Cruda'!$K$2:$K$1801,'Data Cruda'!$A$2:$A$1801,2025,'Data Cruda'!$C$2:$C$1801,"Octubre"),0) -> 0.1750591 | L40: =IFERROR(SUMIFS('Data Cruda'!$P$2:$P$1801,'Data Cruda'!$A$2:$A$1801,2025,'Data Cruda'!$C$2:$C$1801,"Noviembre")/SUMIFS('Data Cruda'!$K$2:$K$1801,'Data Cruda'!$A$2:$A$1801,2025,'Data Cruda'!$C$2:$C$1801,"Noviembre"),0) -> 0.17220737 | M40: =IFERROR(SUMIFS('Data Cruda'!$P$2:$P$1801,'Data Cruda'!$A$2:$A$1801,2025,'Data Cruda'!$C$2:$C$1801,"Diciembre")/SUMIFS('Data Cruda'!$K$2:$K$1801,'Data Cruda'!$A$2:$A$1801,2025,'Data Cruda'!$C$2:$C$1801,"Diciembre"),0) -> 0.14195359 | N40: =IFERROR(SUMIFS('Data Cruda'!$P$2:$P$1801,'Data Cruda'!$A$2:$A$1801,2025)/SUMIFS('Data Cruda'!$K$2:$K$1801,'Data Cruda'!$A$2:$A$1801,2025),0) -> 0.16103777
A41: Acum. | B41: =IFERROR(SUMPRODUCT(('Data Cruda'!$A$2:$A$1801=2025)*ISNUMBER(MATCH('Data Cruda'!$C$2:$C$1801,{"Enero"},0))*'Data Cruda'!$P$2:$P$1801)/SUMPRODUCT(('Data Cruda'!$A$2:$A$1801=2025)*ISNUMBER(MATCH('Data Cruda'!$C$2:$C$1801,{"Enero"},0))*'Data Cruda'!$K$2:$K$1801),0) -> 0.15202929 | C41: =IFERROR(SUMPRODUCT(('Data Cruda'!$A$2:$A$1801=2025)*ISNUMBER(MATCH('Data Cruda'!$C$2:$C$1801,{"Enero","Febrero"},0))*'Data Cruda'!$P$2:$P$1801)/SUMPRODUCT(('Data Cruda'!$A$2:$A$1801=2025)*ISNUMBER(MATCH('Data Cruda'!$C$2:$C$1801,{"Enero","Febrero"},0))*'Data Cruda'!$K$2:$K$1801),0) -> 0.15475572 | D41: =IFERROR(SUMPRODUCT(('Data Cruda'!$A$2:$A$1801=2025)*ISNUMBER(MATCH('Data Cruda'!$C$2:$C$1801,{"Enero","Febrero","Marzo"},0))*'Data Cruda'!$P$2:$P$1801)/SUMPRODUCT(('Data Cruda'!$A$2:$A$1801=2025)*ISNUMBER(MATCH('Data Cruda'!$C$2:$C$1801,{"Enero","Febrero","Marzo"},0))*'Data Cruda'!$K$2:$K$1801),0) -> 0.15155593 | E41: =IFERROR(SUMPRODUCT(('Data Cruda'!$A$2:$A$1801=2025)*ISNUMBER(MATCH('Data Cruda'!$C$2:$C$1801,{"Enero","Febrero","Marzo","Abril"},0))*'Data Cruda'!$P$2:$P$1801)/SUMPRODUCT(('Data Cruda'!$A$2:$A$1801=2025)*ISNUMBER(MATCH('Data Cruda'!$C$2:$C$1801,{"Enero","Febrero","Marzo","Abril"},0))*'Data Cruda'!$K$2:$K$1801),0) -> 0.15882619 | F41: =IFERROR(SUMPRODUCT(('Data Cruda'!$A$2:$A$1801=2025)*ISNUMBER(MATCH('Data Cruda'!$C$2:$C$1801,{"Enero","Febrero","Marzo","Abril","Mayo"},0))*'Data Cruda'!$P$2:$P$1801)/SUMPRODUCT(('Data Cruda'!$A$2:$A$1801=2025)*ISNUMBER(MATCH('Data Cruda'!$C$2:$C$1801,{"Enero","Febrero","Marzo","Abril","Mayo"},0))*'Data Cruda'!$K$2:$K$1801),0) -> 0.15968127 | G41: =IFERROR(SUMPRODUCT(('Data Cruda'!$A$2:$A$1801=2025)*ISNUMBER(MATCH('Data Cruda'!$C$2:$C$1801,{"Enero","Febrero","Marzo","Abril","Mayo","Junio"},0))*'Data Cruda'!$P$2:$P$1801)/SUMPRODUCT(('Data Cruda'!$A$2:$A$1801=2025)*ISNUMBER(MATCH('Data Cruda'!$C$2:$C$1801,{"Enero","Febrero","Marzo","Abril","Mayo","Junio"},0))*'Data Cruda'!$K$2:$K$1801),0) -> 0.15535511 | H41: =IFERROR(SUMPRODUCT(('Data Cruda'!$A$2:$A$1801=2025)*ISNUMBER(MATCH('Data Cruda'!$C$2:$C$1801,{"Enero","Febrero","Marzo","Abril","Mayo","Junio","Julio"},0))*'Data Cruda'!$P$2:$P$1801)/SUMPRODUCT(('Data Cruda'!$A$2:$A$1801=2025)*ISNUMBER(MATCH('Data Cruda'!$C$2:$C$1801,{"Enero","Febrero","Marzo","Abril","Mayo","Junio","Julio"},0))*'Data Cruda'!$K$2:$K$1801),0) -> 0.15482751 | I41: =IFERROR(SUMPRODUCT(('Data Cruda'!$A$2:$A$1801=2025)*ISNUMBER(MATCH('Data Cruda'!$C$2:$C$1801,{"Enero","Febrero","Marzo","Abril","Mayo","Junio","Julio","Agosto"},0))*'Data Cruda'!$P$2:$P$1801)/SUMPRODUCT(('Data Cruda'!$A$2:$A$1801=2025)*ISNUMBER(MATCH('Data Cruda'!$C$2:$C$1801,{"Enero","Febrero","Marzo","Abril","Mayo","Junio","Julio","Agosto"},0))*'Data Cruda'!$K$2:$K$1801),0) -> 0.15927347 | J41: =IFERROR(SUMPRODUCT(('Data Cruda'!$A$2:$A$1801=2025)*ISNUMBER(MATCH('Data Cruda'!$C$2:$C$1801,{"Enero","Febrero","Marzo","Abril","Mayo","Junio","Julio","Agosto","Setiembre"},0))*'Data Cruda'!$P$2:$P$1801)/SUMPRODUCT(('Data Cruda'!$A$2:$A$1801=2025)*ISNUMBER(MATCH('Data Cruda'!$C$2:$C$1801,{"Enero","Febrero","Marzo","Abril","Mayo","Junio","Julio","Agosto","Setiembre"},0))*'Data Cruda'!$K$2:$K$1801),0) -> 0.15981246 | K41: =IFERROR(SUMPRODUCT(('Data Cruda'!$A$2:$A$1801=2025)*ISNUMBER(MATCH('Data Cruda'!$C$2:$C$1801,{"Enero","Febrero","Marzo","Abril","Mayo","Junio","Julio","Agosto","Setiembre","Octubre"},0))*'Data Cruda'!$P$2:$P$1801)/SUMPRODUCT(('Data Cruda'!$A$2:$A$1801=2025)*ISNUMBER(MATCH('Data Cruda'!$C$2:$C$1801,{"Enero","Febrero","Marzo","Abril","Mayo","Junio","Julio","Agosto","Setiembre","Octubre"},0))*'Data Cruda'!$K$2:$K$1801),0) -> 0.16078207 | L41: =IFERROR(SUMPRODUCT(('Data Cruda'!$A$2:$A$1801=2025)*ISNUMBER(MATCH('Data Cruda'!$C$2:$C$1801,{"Enero","Febrero","Marzo","Abril","Mayo","Junio","Julio","Agosto","Setiembre","Octubre","Noviembre"},0))*'Data Cruda'!$P$2:$P$1801)/SUMPRODUCT(('Data Cruda'!$A$2:$A$1801=2025)*ISNUMBER(MATCH('Data Cruda'!$C$2:$C$1801,{"Enero","Febrero","Marzo","Abril","Mayo","Junio","Julio","Agosto","Setiembre","Octubre","Noviembre"},0))*'Data Cruda'!$K$2:$K$1801),0) -> 0.16160514 | M41: =IFERROR(SUMPRODUCT(('Data Cruda'!$A$2:$A$1801=2025)*ISNUMBER(MATCH('Data Cruda'!$C$2:$C$1801,{"Enero","Febrero","Marzo","Abril","Mayo","Junio","Julio","Agosto","Setiembre","Octubre","Noviembre","Diciembre"},0))*'Data Cruda'!$P$2:$P$1801)/SUMPRODUCT(('Data Cruda'!$A$2:$A$1801=2025)*ISNUMBER(MATCH('Data Cruda'!$C$2:$C$1801,{"Enero","Febrero","Marzo","Abril","Mayo","Junio","Julio","Agosto","Setiembre","Octubre","Noviembre","Diciembre"},0))*'Data Cruda'!$K$2:$K$1801),0) -> 0.16103777 | N41: =N40 -> 0.16103777
A43: 2026 | B43: =IFERROR(SUMIFS('Data Cruda'!$P$2:$P$1801,'Data Cruda'!$A$2:$A$1801,2026,'Data Cruda'!$C$2:$C$1801,"Enero")/SUMIFS('Data Cruda'!$K$2:$K$1801,'Data Cruda'!$A$2:$A$1801,2026,'Data Cruda'!$C$2:$C$1801,"Enero"),0) -> 0.15097763 | C43: =IFERROR(SUMIFS('Data Cruda'!$P$2:$P$1801,'Data Cruda'!$A$2:$A$1801,2026,'Data Cruda'!$C$2:$C$1801,"Febrero")/SUMIFS('Data Cruda'!$K$2:$K$1801,'Data Cruda'!$A$2:$A$1801,2026,'Data Cruda'!$C$2:$C$1801,"Febrero"),0) -> 0.16585125 | D43: =IFERROR(SUMIFS('Data Cruda'!$P$2:$P$1801,'Data Cruda'!$A$2:$A$1801,2026,'Data Cruda'!$C$2:$C$1801,"Marzo")/SUMIFS('Data Cruda'!$K$2:$K$1801,'Data Cruda'!$A$2:$A$1801,2026,'Data Cruda'!$C$2:$C$1801,"Marzo"),0) -> 0.18087268 | E43: =IFERROR(SUMIFS('Data Cruda'!$P$2:$P$1801,'Data Cruda'!$A$2:$A$1801,2026,'Data Cruda'!$C$2:$C$1801,"Abril")/SUMIFS('Data Cruda'!$K$2:$K$1801,'Data Cruda'!$A$2:$A$1801,2026,'Data Cruda'!$C$2:$C$1801,"Abril"),0) -> 0.18255141 | F43: =IFERROR(SUMIFS('Data Cruda'!$P$2:$P$1801,'Data Cruda'!$A$2:$A$1801,2026,'Data Cruda'!$C$2:$C$1801,"Mayo")/SUMIFS('Data Cruda'!$K$2:$K$1801,'Data Cruda'!$A$2:$A$1801,2026,'Data Cruda'!$C$2:$C$1801,"Mayo"),0) -> 0.14024809 | G43: =IFERROR(SUMIFS('Data Cruda'!$P$2:$P$1801,'Data Cruda'!$A$2:$A$1801,2026,'Data Cruda'!$C$2:$C$1801,"Junio")/SUMIFS('Data Cruda'!$K$2:$K$1801,'Data Cruda'!$A$2:$A$1801,2026,'Data Cruda'!$C$2:$C$1801,"Junio"),0) -> 0.15065386 | H43: =IFERROR(SUMIFS('Data Cruda'!$P$2:$P$1801,'Data Cruda'!$A$2:$A$1801,2026,'Data Cruda'!$C$2:$C$1801,"Julio")/SUMIFS('Data Cruda'!$K$2:$K$1801,'Data Cruda'!$A$2:$A$1801,2026,'Data Cruda'!$C$2:$C$1801,"Julio"),0) -> 0 | I43: =IFERROR(SUMIFS('Data Cruda'!$P$2:$P$1801,'Data Cruda'!$A$2:$A$1801,2026,'Data Cruda'!$C$2:$C$1801,"Agosto")/SUMIFS('Data Cruda'!$K$2:$K$1801,'Data Cruda'!$A$2:$A$1801,2026,'Data Cruda'!$C$2:$C$1801,"Agosto"),0) -> 0 | J43: =IFERROR(SUMIFS('Data Cruda'!$P$2:$P$1801,'Data Cruda'!$A$2:$A$1801,2026,'Data Cruda'!$C$2:$C$1801,"Setiembre")/SUMIFS('Data Cruda'!$K$2:$K$1801,'Data Cruda'!$A$2:$A$1801,2026,'Data Cruda'!$C$2:$C$1801,"Setiembre"),0) -> 0 | K43: =IFERROR(SUMIFS('Data Cruda'!$P$2:$P$1801,'Data Cruda'!$A$2:$A$1801,2026,'Data Cruda'!$C$2:$C$1801,"Octubre")/SUMIFS('Data Cruda'!$K$2:$K$1801,'Data Cruda'!$A$2:$A$1801,2026,'Data Cruda'!$C$2:$C$1801,"Octubre"),0) -> 0 | L43: =IFERROR(SUMIFS('Data Cruda'!$P$2:$P$1801,'Data Cruda'!$A$2:$A$1801,2026,'Data Cruda'!$C$2:$C$1801,"Noviembre")/SUMIFS('Data Cruda'!$K$2:$K$1801,'Data Cruda'!$A$2:$A$1801,2026,'Data Cruda'!$C$2:$C$1801,"Noviembre"),0) -> 0 | M43: =IFERROR(SUMIFS('Data Cruda'!$P$2:$P$1801,'Data Cruda'!$A$2:$A$1801,2026,'Data Cruda'!$C$2:$C$1801,"Diciembre")/SUMIFS('Data Cruda'!$K$2:$K$1801,'Data Cruda'!$A$2:$A$1801,2026,'Data Cruda'!$C$2:$C$1801,"Diciembre"),0) -> 0 | N43: =IFERROR(SUMIFS('Data Cruda'!$P$2:$P$1801,'Data Cruda'!$A$2:$A$1801,2026)/SUMIFS('Data Cruda'!$K$2:$K$1801,'Data Cruda'!$A$2:$A$1801,2026),0) -> 0.15315612
A44: Acum. | B44: =IFERROR(SUMPRODUCT(('Data Cruda'!$A$2:$A$1801=2026)*ISNUMBER(MATCH('Data Cruda'!$C$2:$C$1801,{"Enero"},0))*'Data Cruda'!$P$2:$P$1801)/SUMPRODUCT(('Data Cruda'!$A$2:$A$1801=2026)*ISNUMBER(MATCH('Data Cruda'!$C$2:$C$1801,{"Enero"},0))*'Data Cruda'!$K$2:$K$1801),0) -> 0.15097763 | C44: =IFERROR(SUMPRODUCT(('Data Cruda'!$A$2:$A$1801=2026)*ISNUMBER(MATCH('Data Cruda'!$C$2:$C$1801,{"Enero","Febrero"},0))*'Data Cruda'!$P$2:$P$1801)/SUMPRODUCT(('Data Cruda'!$A$2:$A$1801=2026)*ISNUMBER(MATCH('Data Cruda'!$C$2:$C$1801,{"Enero","Febrero"},0))*'Data Cruda'!$K$2:$K$1801),0) -> 0.1576807 | D44: =IFERROR(SUMPRODUCT(('Data Cruda'!$A$2:$A$1801=2026)*ISNUMBER(MATCH('Data Cruda'!$C$2:$C$1801,{"Enero","Febrero","Marzo"},0))*'Data Cruda'!$P$2:$P$1801)/SUMPRODUCT(('Data Cruda'!$A$2:$A$1801=2026)*ISNUMBER(MATCH('Data Cruda'!$C$2:$C$1801,{"Enero","Febrero","Marzo"},0))*'Data Cruda'!$K$2:$K$1801),0) -> 0.15900671 | E44: =IFERROR(SUMPRODUCT(('Data Cruda'!$A$2:$A$1801=2026)*ISNUMBER(MATCH('Data Cruda'!$C$2:$C$1801,{"Enero","Febrero","Marzo","Abril"},0))*'Data Cruda'!$P$2:$P$1801)/SUMPRODUCT(('Data Cruda'!$A$2:$A$1801=2026)*ISNUMBER(MATCH('Data Cruda'!$C$2:$C$1801,{"Enero","Febrero","Marzo","Abril"},0))*'Data Cruda'!$K$2:$K$1801),0) -> 0.16692422 | F44: =IFERROR(SUMPRODUCT(('Data Cruda'!$A$2:$A$1801=2026)*ISNUMBER(MATCH('Data Cruda'!$C$2:$C$1801,{"Enero","Febrero","Marzo","Abril","Mayo"},0))*'Data Cruda'!$P$2:$P$1801)/SUMPRODUCT(('Data Cruda'!$A$2:$A$1801=2026)*ISNUMBER(MATCH('Data Cruda'!$C$2:$C$1801,{"Enero","Febrero","Marzo","Abril","Mayo"},0))*'Data Cruda'!$K$2:$K$1801),0) -> 0.15340179 | G44: =IFERROR(SUMPRODUCT(('Data Cruda'!$A$2:$A$1801=2026)*ISNUMBER(MATCH('Data Cruda'!$C$2:$C$1801,{"Enero","Febrero","Marzo","Abril","Mayo","Junio"},0))*'Data Cruda'!$P$2:$P$1801)/SUMPRODUCT(('Data Cruda'!$A$2:$A$1801=2026)*ISNUMBER(MATCH('Data Cruda'!$C$2:$C$1801,{"Enero","Febrero","Marzo","Abril","Mayo","Junio"},0))*'Data Cruda'!$K$2:$K$1801),0) -> 0.15315612 | N44: =N43 -> 0.15315612

Sheet 2. Análisis Anual
A1: TABLA 1 – REFRIGERANTE: FREÓN VS OTROS
A3: Año | B3: Monto Freón | C3: % Freón | D3: Monto Otros | E3: % Otros | F3: Total Año
A4: 2021 | B4: 9717808.6 | C4: =B4/F4 -> 0.47846133 | D4: =F4-B4 -> 10592733 | E4: =D4/F4 -> 0.52153867 | F4: 20310541
A5: 2022 | B5: 11783033 | C5: =B5/F5 -> 0.35491316 | D5: =F5-B5 -> 21416731 | E5: =D5/F5 -> 0.64508684 | F5: 33199765
A6: 2023 | B6: 10023577 | C6: =B6/F6 -> 0.65559102 | D6: =F6-B6 -> 5265798.1 | E6: =D6/F6 -> 0.34440898 | F6: 15289375
A7: 2024 | B7: 6480103.8 | C7: =B7/F7 -> 0.41939299 | D7: =F7-B7 -> 8971045.5 | E7: =D7/F7 -> 0.58060701 | F7: 15451149
A8: 2025 | B8: 6662323.2 | C8: =B8/F8 -> 0.19058992 | D8: =F8-B8 -> 28294001 | E8: =D8/F8 -> 0.80941008 | F8: 34956324
A9: 2026 | B9: 4913328.2 | C9: =B9/F9 -> 0.17385753 | D9: =F9-B9 -> 23347329 | E9: =D9/F9 -> 0.82614247 | F9: 28260657
A10: TOTAL | B10: 49580174 | C10: 0.33621014 | D10: 97887637 | E10: 0.66378986 | F10: 1.4746781e+08
A13: TABLA 2 – MARGEN POR REFRIGERANTE (FREÓN / AMONIACO / OTROS)
A15: Año | B15: Freón Monto | C15: Freón Mg% | D15: Freón %Part | E15: Amon. Monto | F15: Amon. Mg% | G15: Amon. %Part | H15: Otros Monto | I15: Otros Mg% | J15: Otros %Part | K15: Total
